forrtl: No such file or directory
forrtl: severe (29): file not found, unit 30, file /home/mkb/GitHub/learningForces/krrThomas/results.tag
Image              PC                Routine            Line        Source             
dftb+_1.2.1.x86_6  0000000001DB156A  Unknown               Unknown  Unknown
dftb+_1.2.1.x86_6  0000000001DB0066  Unknown               Unknown  Unknown
dftb+_1.2.1.x86_6  0000000001D5DCA0  Unknown               Unknown  Unknown
dftb+_1.2.1.x86_6  0000000001D11B6F  Unknown               Unknown  Unknown
dftb+_1.2.1.x86_6  0000000001D11077  Unknown               Unknown  Unknown
dftb+_1.2.1.x86_6  0000000001D2545D  Unknown               Unknown  Unknown
dftb+_1.2.1.x86_6  000000000042A64C  Unknown               Unknown  Unknown
dftb+_1.2.1.x86_6  000000000040045C  Unknown               Unknown  Unknown
dftb+_1.2.1.x86_6  0000000001DC086E  Unknown               Unknown  Unknown
dftb+_1.2.1.x86_6  0000000000400329  Unknown               Unknown  Unknown
Traceback (most recent call last):
  File "globalOptim_ase3d.py", line 582, in <module>
    optimizer.runOptimizer()
  File "globalOptim_ase3d.py", line 368, in runOptimizer
    a, E = self.relax(a_init, ML=False)
  File "globalOptim_ase3d.py", line 495, in relax
    relax_VarianceBreak(a, self.calculator, label)
  File "globalOptim_ase3d.py", line 46, in relax_VarianceBreak
    dyn.run(fmax = forcemax, steps = 500)
  File "/home/mkb/virtualEnvs/python-3.6.3/lib/python3.6/site-packages/ase/optimize/optimize.py", line 174, in run
    f = self.atoms.get_forces()
  File "/home/mkb/virtualEnvs/python-3.6.3/lib/python3.6/site-packages/ase/atoms.py", line 734, in get_forces
    forces = self._calc.get_forces(self)
  File "/home/mkb/virtualEnvs/python-3.6.3/lib/python3.6/site-packages/ase/calculators/calculator.py", line 453, in get_forces
    return self.get_property('forces', atoms)
  File "/home/mkb/virtualEnvs/python-3.6.3/lib/python3.6/site-packages/ase/calculators/calculator.py", line 486, in get_property
    self.calculate(atoms, [name], system_changes)
  File "/home/mkb/virtualEnvs/python-3.6.3/lib/python3.6/site-packages/ase/calculators/calculator.py", line 649, in calculate
    .format(self.name, self.directory, errorcode))
RuntimeError: dftb in . returned an error: 29
